[2023-07-29T09:03:34.508+0000] {taskinstance.py:1103} INFO - Dependencies all met for dep_context=non-requeueable deps ti=<TaskInstance: simple_dbt_dag.dbt_run scheduled__2023-07-28T00:00:00+00:00 [queued]>
[2023-07-29T09:03:34.618+0000] {taskinstance.py:1103} INFO - Dependencies all met for dep_context=requeueable deps ti=<TaskInstance: simple_dbt_dag.dbt_run scheduled__2023-07-28T00:00:00+00:00 [queued]>
[2023-07-29T09:03:34.625+0000] {taskinstance.py:1308} INFO - Starting attempt 1 of 1
[2023-07-29T09:03:34.767+0000] {taskinstance.py:1327} INFO - Executing <Task(BashOperator): dbt_run> on 2023-07-28 00:00:00+00:00
[2023-07-29T09:03:34.783+0000] {standard_task_runner.py:84} INFO - Running: ['***', 'tasks', 'run', 'simple_dbt_dag', 'dbt_run', 'scheduled__2023-07-28T00:00:00+00:00', '--job-id', '282', '--raw', '--subdir', 'DAGS_FOLDER/test.py', '--cfg-path', '/tmp/tmp3c9r794t']
[2023-07-29T09:03:34.775+0000] {standard_task_runner.py:57} INFO - Started process 2155 to run task
[2023-07-29T09:03:34.812+0000] {standard_task_runner.py:85} INFO - Job 282: Subtask dbt_run
[2023-07-29T09:03:35.182+0000] {task_command.py:410} INFO - Running <TaskInstance: simple_dbt_dag.dbt_run scheduled__2023-07-28T00:00:00+00:00 [running]> on host e6ac5424eb0d
[2023-07-29T09:03:35.798+0000] {taskinstance.py:1547} INFO - Exporting env vars: AIRFLOW_CTX_DAG_OWNER='***' AIRFLOW_CTX_DAG_ID='simple_dbt_dag' AIRFLOW_CTX_TASK_ID='dbt_run' AIRFLOW_CTX_EXECUTION_DATE='2023-07-28T00:00:00+00:00' AIRFLOW_CTX_TRY_NUMBER='1' AIRFLOW_CTX_DAG_RUN_ID='scheduled__2023-07-28T00:00:00+00:00'
[2023-07-29T09:03:35.813+0000] {subprocess.py:63} INFO - Tmp dir root location: /tmp
[2023-07-29T09:03:35.820+0000] {subprocess.py:75} INFO - Running command: ['/bin/bash', '-c', 'source $PATH_TO_DBT_VENV && dbt run --models .']
[2023-07-29T09:03:35.867+0000] {subprocess.py:86} INFO - Output:
[2023-07-29T09:03:35.904+0000] {subprocess.py:93} INFO - /bin/bash: line 1: dbt: command not found
[2023-07-29T09:03:35.906+0000] {subprocess.py:97} INFO - Command exited with return code 127
[2023-07-29T09:03:35.992+0000] {taskinstance.py:1824} ERROR - Task failed with exception
Traceback (most recent call last):
  File "/home/airflow/.local/lib/python3.7/site-packages/airflow/operators/bash.py", line 211, in execute
    f"Bash command failed. The command returned a non-zero exit code {result.exit_code}."
airflow.exceptions.AirflowException: Bash command failed. The command returned a non-zero exit code 127.
[2023-07-29T09:03:36.010+0000] {taskinstance.py:1350} INFO - Marking task as FAILED. dag_id=simple_dbt_dag, task_id=dbt_run, execution_date=20230728T000000, start_date=20230729T090334, end_date=20230729T090336
[2023-07-29T09:03:36.187+0000] {standard_task_runner.py:109} ERROR - Failed to execute job 282 for task dbt_run (Bash command failed. The command returned a non-zero exit code 127.; 2155)
[2023-07-29T09:03:36.284+0000] {local_task_job_runner.py:225} INFO - Task exited with return code 1
[2023-07-29T09:03:36.428+0000] {taskinstance.py:2653} INFO - 0 downstream tasks scheduled from follow-on schedule check
